
    <mujoco model="Snake">
    <option timestep="0.01"/>

    <asset>
        <texture type="skybox" builtin="gradient" rgb1=".3 .5 .7" rgb2="0 0 0" width="512" height="512"/>
        <texture name="body" type="cube" builtin="flat" mark="cross" width="127" height="1278"
                 rgb1="0.8 0.6 0.4" rgb2="0.8 0.6 0.4" markrgb="1 1 1" random="0.01"/>
        <material name="body" texture="body" texuniform="true" rgba="0.8 0.6 .4 1"/>
        <texture name="grid" type="2d" builtin="checker" width="512" height="512" rgb1=".1 .2 .3" rgb2=".2 .3 .4"/>
        <material name="grid" texture="grid" texrepeat="1 1" texuniform="true" reflectance=".2"/>
    </asset>

    <default>
        <motor ctrlrange="-1 1" ctrllimited="true"/>
        <default class="body">
            <geom type="capsule" condim="6" friction=".7" solimp=".9 .99 .003" solref=".015 1" material="body"/>
            <joint type="hinge" damping=".2" stiffness="1" armature=".01" limited="true" solimplimit="0 .99 .01"/>
          </default>
    </default>

    <visual>
        <map force="0.1" zfar="30"/>
        <rgba haze="0.9 0.9 0.15 1"/>
        <quality shadowsize="4096"/>
        <global offwidth="800" offheight="800"/>
    </visual>
    
    <worldbody>
        <geom name="floor" size="0 0 .05" type="plane" material="grid" condim="3"/>
        <light name="spotlight" mode="targetbodycom" target="head"
            diffuse=".8 .8 .8" specular="0.3 0.3 0.3" pos="0 -20 4" cutoff="10"/>

        <body name="head" pos="0 0 0.5" childclass="body">
            <light name="top" pos="0 0 2" mode="trackcom"/>
            <camera name="back" pos="-3 0 1" xyaxes="0 -1 0 1 0 2" mode="trackcom"/>
            <camera name="side" pos="0 -3 1" xyaxes="1 0 0 0 1 2" mode="trackcom"/>
            <freejoint name="root"/>
            <geom name="head" fromto="0 0 0 0.1 0 0" size=".06"/>
    
            <body name="segment_0" pos="0.1 0 0 ">
                <geom name="segment_0" fromto="0 0 0 0.1 0 0" size=".05"/>
                <joint name="curl_0" pos="0 0 0" axis="0 1 0" range="-45 45"/>
            
            <body name="segment_1" pos="0.1 0 0 ">
                <geom name="segment_1" fromto="0 0 0 0.1 0 0" size=".05"/>
                <joint name="twist_1" pos="0 0 0" axis="1 0 0" range="-10 10"/>
            
            <body name="segment_2" pos="0.1 0 0 ">
                <geom name="segment_2" fromto="0 0 0 0.1 0 0" size=".05"/>
                <joint name="curl_2" pos="0 0 0" axis="0 1 0" range="-45 45"/>
            
            <body name="segment_3" pos="0.1 0 0 ">
                <geom name="segment_3" fromto="0 0 0 0.1 0 0" size=".05"/>
                <joint name="curl_3" pos="0 0 0" axis="0 1 0" range="-45 45"/>
            
            <body name="segment_4" pos="0.1 0 0 ">
                <geom name="segment_4" fromto="0 0 0 0.1 0 0" size=".05"/>
                <joint name="curl_4" pos="0 0 0" axis="0 1 0" range="-45 45"/>
            
            <body name="segment_5" pos="0.1 0 0 ">
                <geom name="segment_5" fromto="0 0 0 0.1 0 0" size=".05"/>
                <joint name="curl_5" pos="0 0 0" axis="0 1 0" range="-45 45"/>
            
            <body name="segment_6" pos="0.1 0 0 ">
                <geom name="segment_6" fromto="0 0 0 0.1 0 0" size=".05"/>
                <joint name="twist_6" pos="0 0 0" axis="1 0 0" range="-10 10"/>
            
    </body>
    
        </body>
        
        </body>
        
        </body>
        
        </body>
        
        </body>
        
        </body>
        
        </body>
        
    </worldbody>
    
    <actuator>
    
            <motor name="curl_0"  gear="40"  joint="curl_0"/>
            
            <motor name="twist_1"  gear="120"  joint="twist_1"/>
            
            <motor name="curl_2"  gear="40"  joint="curl_2"/>
            
            <motor name="curl_3"  gear="40"  joint="curl_3"/>
            
            <motor name="curl_4"  gear="40"  joint="curl_4"/>
            
            <motor name="curl_5"  gear="40"  joint="curl_5"/>
            
            <motor name="twist_6"  gear="120"  joint="twist_6"/>
            
    </actuator>
    
    </mujoco>
    